path.existsSync is now called `fs.existsSync`.
Application has thrown an uncaught exception and is terminated:
Error: failed to connect to [ds027758.mongolab.com:27758]
    at Server.connect.connectionPool.on.server._serverState (C:\Users\feriese\Documents\My Web Sites\mountainandgiant\node_modules\mongoose\node_modules\mongodb\lib\mongodb\connection\server.js:540:74)
    at EventEmitter.emit (events.js:126:20)
    at connection.on._self._poolState (C:\Users\feriese\Documents\My Web Sites\mountainandgiant\node_modules\mongoose\node_modules\mongodb\lib\mongodb\connection\connection_pool.js:140:15)
    at EventEmitter.emit (events.js:99:17)
    at Socket.errorHandler (C:\Users\feriese\Documents\My Web Sites\mountainandgiant\node_modules\mongoose\node_modules\mongodb\lib\mongodb\connection\connection.js:478:10)
    at Socket.EventEmitter.emit (events.js:96:17)
    at Socket.connect.require.lookup.addressType (net.js:699:16)
    at process.startup.processNextTick.process._tickCallback (node.js:244:9)
